Workbook

Sheet Consultant NFI League
B2: Q1 NFI ZAR | L2: Q1 NFI USD | M2: 16.67 | V2: Q1 NFI GBP | W2: 22.3
B4: Consultant / Month | C4: Perm / Temp | D4: Business | E4: Apr | F4: May | G4: Jun | H4: Q1 Actual | I4: Q1 Target | J4: % Achieved | L4: Consultant / Month | M4: Perm / Temp | N4: Business | O4: Apr | P4: May | Q4: Jun | R4: Q1 Actual | S4: Q1 Target | T4: % Achieved | V4: Consultant / Month | W4: Perm / Temp | X4: Business | Y4: Apr | Z4: May | AA4: Jun | AB4: Q1 Actual | AC4: Q1 Target | AD4: % Achieved
B5: Lee Bishop | C5: PERM | D5: S4 Energy | H5: =SUM(E5:G5) -> 0 | I5: 900000 | J5: =H5/I5 -> 0 | L5: Lee Bishop | M5: PERM | N5: S4 Energy | O5: =E5/$M$2 -> 0 | P5: =F5/$M$2 -> 0 | Q5: =G5/$M$2 -> 0 | R5: =H5/$M$2 -> 0 | S5: =I5/$M$2 -> 53989.202 | V5: Lee Bishop | W5: PERM | X5: S4 Energy | Y5: =E5/$W$2 -> 0 | Z5: =F5/$W$2 -> 0 | AA5: =G5/$W$2 -> 0 | AB5: =H5/$W$2 -> 0 | AC5: =I5/$W$2 -> 40358.744
B6: Warren Beder | C6: PERM | D6: S4 Energy | E6: ='Perm NFI data'!AD32 -> 74250 | H6: =SUM(E6:G6) -> 74250 | I6: 900000 | J6: =H6/I6 -> 0.0825 | L6: Warren Beder | M6: PERM | N6: S4 Energy | O6: =E6/$M$2 -> 4454.1092 | P6: =F6/$M$2 -> 0 | Q6: =G6/$M$2 -> 0 | R6: =H6/$M$2 -> 4454.1092 | S6: =I6/$M$2 -> 53989.202 | V6: Warren Beder | W6: PERM | X6: S4 Energy | Y6: =E6/$W$2 -> 3329.5964 | Z6: =F6/$W$2 -> 0 | AA6: =G6/$W$2 -> 0 | AB6: =H6/$W$2 -> 3329.5964 | AC6: =I6/$W$2 -> 40358.744
B7: Lufuno Orji* | C7: PERM | D7: S4 Energy | E7: ='Perm NFI data'!AE32 -> 74250 | H7: =SUM(E7:G7) -> 74250 | I7: 525000 | J7: =H7/I7 -> 0.14142857 | L7: Lufuno Orji* | M7: PERM | N7: S4 Energy | O7: =E7/$M$2 -> 4454.1092 | P7: =F7/$M$2 -> 0 | Q7: =G7/$M$2 -> 0 | R7: =H7/$M$2 -> 4454.1092 | S7: =I7/$M$2 -> 31493.701 | V7: Lufuno Orji* | W7: PERM | X7: S4 Energy | Y7: =E7/$W$2 -> 3329.5964 | Z7: =F7/$W$2 -> 0 | AA7: =G7/$W$2 -> 0 | AB7: =H7/$W$2 -> 3329.5964 | AC7: =I7/$W$2 -> 23542.601
B8: Kyla Morgan | C8: PERM | D8: S4 Energy | E8: ='S4 Cloud Contractor Data'!C91 -> 12000 | F8: ='S4 Cloud Contractor Data'!D91 -> 12000 | G8: ='S4 Cloud Contractor Data'!E91 -> 12000 | H8: =SUM(E8:G8) -> 36000 | I8: 510000 | J8: =H8/I8 -> 0.070588235 | L8: Kyla Morgan | M8: PERM | N8: S4 Energy | O8: =E8/$M$2 -> 719.85603 | P8: =F8/$M$2 -> 719.85603 | Q8: =G8/$M$2 -> 719.85603 | R8: =H8/$M$2 -> 2159.5681 | S8: =I8/$M$2 -> 30593.881 | V8: Kyla Morgan | W8: PERM | X8: S4 Energy | Y8: =E8/$W$2 -> 538.11659 | Z8: =F8/$W$2 -> 538.11659 | AA8: =G8/$W$2 -> 538.11659 | AB8: =H8/$W$2 -> 1614.3498 | AC8: =I8/$W$2 -> 22869.955
B9: Zara Kavalieratos | C9: PERM | D9: S4 Energy | H9: =SUM(E9:G9) -> 0 | I9: 450000 | J9: =H9/I9 -> 0 | L9: Zara Kavalieratos | M9: PERM | N9: S4 Energy | O9: =E9/$M$2 -> 0 | P9: =F9/$M$2 -> 0 | Q9: =G9/$M$2 -> 0 | R9: =H9/$M$2 -> 0 | S9: =I9/$M$2 -> 26994.601 | V9: Zara Kavalieratos | W9: PERM | X9: S4 Energy | Y9: =E9/$W$2 -> 0 | Z9: =F9/$W$2 -> 0 | AA9: =G9/$W$2 -> 0 | AB9: =H9/$W$2 -> 0 | AC9: =I9/$W$2 -> 20179.372
B10: JP Roos | C10: PERM | D10: S4 Energy | H10: =SUM(E10:G10) -> 0 | I10: 450000 | J10: =H10/I10 -> 0 | L10: JP Roos | M10: PERM | N10: S4 Energy | O10: =E10/$M$2 -> 0 | P10: =F10/$M$2 -> 0 | Q10: =G10/$M$2 -> 0 | R10: =H10/$M$2 -> 0 | S10: =I10/$M$2 -> 26994.601 | V10: JP Roos | W10: PERM | X10: S4 Energy | Y10: =E10/$W$2 -> 0 | Z10: =F10/$W$2 -> 0 | AA10: =G10/$W$2 -> 0 | AB10: =H10/$W$2 -> 0 | AC10: =I10/$W$2 -> 20179.372
B11: Matthew Taylor | C11: PERM | D11: S4 Energy | H11: =SUM(E11:G11) -> 0 | I11: 450000 | J11: =H11/I11 -> 0 | L11: Matthew Taylor | M11: PERM | N11: S4 Energy | O11: =E11/$M$2 -> 0 | P11: =F11/$M$2 -> 0 | Q11: =G11/$M$2 -> 0 | R11: =H11/$M$2 -> 0 | S11: =I11/$M$2 -> 26994.601 | V11: Matthew Taylor | W11: PERM | X11: S4 Energy | Y11: =E11/$W$2 -> 0 | Z11: =F11/$W$2 -> 0 | AA11: =G11/$W$2 -> 0 | AB11: =H11/$W$2 -> 0 | AC11: =I11/$W$2 -> 20179.372
B12: Nicole Samuels* | C12: PERM | D12: S4 Energy | E12: ='S4 Cloud Contractor Data'!C90 -> 15600 | F12: ='S4 Cloud Contractor Data'!D90 -> 15600 | G12: ='S4 Cloud Contractor Data'!E90 -> 15600 | H12: =SUM(E12:G12) -> 46800 | I12: 648000 | J12: =H12/I12 -> 0.072222222 | L12: Nicole Samuels* | M12: PERM | N12: S4 Energy | O12: =E12/$M$2 -> 935.81284 | P12: =F12/$M$2 -> 935.81284 | Q12: =G12/$M$2 -> 935.81284 | R12: =H12/$M$2 -> 2807.4385 | S12: =I12/$M$2 -> 38872.226 | V12: Nicole Samuels* | W12: PERM | X12: S4 Energy | Y12: =E12/$W$2 -> 699.55157 | Z12: =F12/$W$2 -> 699.55157 | AA12: =G12/$W$2 -> 699.55157 | AB12: =H12/$W$2 -> 2098.6547 | AC12: =I12/$W$2 -> 29058.296
B13: Robyn Andreka | C13: PERM | D13: S4 Energy | H13: =SUM(E13:G13) -> 0 | I13: 405000 | J13: =H13/I13 -> 0 | L13: Robyn Andreka | M13: PERM | N13: S4 Energy | O13: =E13/$M$2 -> 0 | P13: =F13/$M$2 -> 0 | Q13: =G13/$M$2 -> 0 | R13: =H13/$M$2 -> 0 | S13: =I13/$M$2 -> 24295.141 | V13: Robyn Andreka | W13: PERM | X13: S4 Energy | Y13: =E13/$W$2 -> 0 | Z13: =F13/$W$2 -> 0 | AA13: =G13/$W$2 -> 0 | AB13: =H13/$W$2 -> 0 | AC13: =I13/$W$2 -> 18161.435
B14: Nikkita Elliot | C14: PERM | D14: S4 Energy | H14: =SUM(E14:G14) -> 0 | I14: 50000 | J14: =H14/I14 -> 0 | L14: Nikkita Elliot | M14: PERM | N14: S4 Energy | O14: =E14/$M$2 -> 0 | P14: =F14/$M$2 -> 0 | Q14: =G14/$M$2 -> 0 | R14: =H14/$M$2 -> 0 | S14: =I14/$M$2 -> 2999.4001 | V14: Nikkita Elliot | W14: PERM | X14: S4 Energy | Y14: =E14/$W$2 -> 0 | Z14: =F14/$W$2 -> 0 | AA14: =G14/$W$2 -> 0 | AB14: =H14/$W$2 -> 0 | AC14: =I14/$W$2 -> 2242.1525
B15: Mae Alwahi | C15: PERM | D15: S4 Energy | H15: =SUM(E15:G15) -> 0 | I15: 150000 | J15: =H15/I15 -> 0 | L15: Mae Alwahi | M15: PERM | N15: S4 Energy | O15: =E15/$M$2 -> 0 | P15: =F15/$M$2 -> 0 | Q15: =G15/$M$2 -> 0 | R15: =H15/$M$2 -> 0 | S15: =I15/$M$2 -> 8998.2004 | V15: Mae Alwahi | W15: PERM | X15: S4 Energy | Y15: =E15/$W$2 -> 0 | Z15: =F15/$W$2 -> 0 | AA15: =G15/$W$2 -> 0 | AB15: =H15/$W$2 -> 0 | AC15: =I15/$W$2 -> 6726.4574
B16: Chris Butcher | C16: PERM | D16: S4 Energy | H16: =SUM(E16:G16) -> 0 | I16: 300000 | J16: =H16/I16 -> 0 | L16: Christopher Butcher | M16: PERM | N16: S4 Energy | O16: =E16/$M$2 -> 0 | P16: =F16/$M$2 -> 0 | Q16: =G16/$M$2 -> 0 | R16: =H16/$M$2 -> 0 | S16: =I16/$M$2 -> 17996.401 | V16: Christopher Butcher | W16: PERM | X16: S4 Energy | Y16: =E16/$W$2 -> 0 | Z16: =F16/$W$2 -> 0 | AA16: =G16/$W$2 -> 0 | AB16: =H16/$W$2 -> 0 | AC16: =I16/$W$2 -> 13452.915
B17: Lara JVR | C17: PERM | D17: S4 Energy | H17: =SUM(E17:G17) -> 0 | I17: 300000 | J17: =H17/I17 -> 0 | L17: Lara JVR | M17: PERM | N17: S4 Energy | O17: =E17/$M$2 -> 0 | P17: =F17/$M$2 -> 0 | Q17: =G17/$M$2 -> 0 | R17: =H17/$M$2 -> 0 | S17: =I17/$M$2 -> 17996.401 | V17: Lara JVR | W17: PERM | X17: S4 Energy | Y17: =E17/$W$2 -> 0 | Z17: =F17/$W$2 -> 0 | AA17: =G17/$W$2 -> 0 | AB17: =H17/$W$2 -> 0 | AC17: =I17/$W$2 -> 13452.915
B18: Zoe W | C18: PERM | D18: S4 Energy | H18: =SUM(E18:G18) -> 0 | I18: 0 | J18: =H18/I18 -> #DIV/0! | L18: Zoe W | M18: PERM | N18: S4 Energy | O18: =E18/$M$2 -> 0 | P18: =F18/$M$2 -> 0 | Q18: =G18/$M$2 -> 0 | R18: =H18/$M$2 -> 0 | S18: =I18/$M$2 -> 0 | V18: Zoe W | W18: PERM | X18: S4 Energy | Y18: =E18/$W$2 -> 0 | Z18: =F18/$W$2 -> 0 | AA18: =G18/$W$2 -> 0 | AB18: =H18/$W$2 -> 0 | AC18: =I18/$W$2 -> 0
B19: Josh Wegelar | C19: PERM | D19: S4 Energy | H19: =SUM(E19:G19) -> 0 | I19: 0 | J19: =H19/I19 -> #DIV/0! | L19: Josh Wegelar | M19: PERM | N19: S4 Energy | O19: =E19/$M$2 -> 0 | P19: =F19/$M$2 -> 0 | Q19: =G19/$M$2 -> 0 | R19: =H19/$M$2 -> 0 | S19: =I19/$M$2 -> 0 | V19: Josh Wegelar | W19: PERM | X19: S4 Energy | Y19: =E19/$W$2 -> 0 | Z19: =F19/$W$2 -> 0 | AA19: =G19/$W$2 -> 0 | AB19: =H19/$W$2 -> 0 | AC19: =I19/$W$2 -> 0
B20: Nina Jacobs | C20: PERM | D20: S4 Energy | H20: =SUM(E20:G20) -> 0 | I20: 0 | J20: =H20/I20 -> #DIV/0! | L20: Nina Jacobs | M20: PERM | N20: S4 Energy | O20: =E20/$M$2 -> 0 | P20: =F20/$M$2 -> 0 | Q20: =G20/$M$2 -> 0 | R20: =H20/$M$2 -> 0 | S20: =I20/$M$2 -> 0 | V20: Nina Jacobs | W20: PERM | X20: S4 Energy | Y20: =E20/$W$2 -> 0 | Z20: =F20/$W$2 -> 0 | AA20: =G20/$W$2 -> 0 | AB20: =H20/$W$2 -> 0 | AC20: =I20/$W$2 -> 0
B21: Steph Payne | C21: PERM | D21: S4 Cloud | E21: ='S4 Cloud Contractor Data'!C94 -> 0 | F21: ='S4 Cloud Contractor Data'!D94 -> 0 | G21: ='S4 Cloud Contractor Data'!E94 -> 0 | H21: =SUM(E21:G21) -> 0 | I21: 375000 | J21: =H21/I21 -> 0 | L21: Steph Payne | M21: PERM | N21: S4 Cloud | O21: =E21/$M$2 -> 0 | P21: =F21/$M$2 -> 0 | Q21: =G21/$M$2 -> 0 | R21: =H21/$M$2 -> 0 | S21: =I21/$M$2 -> 22495.501 | T21: 0 | V21: Steph Payne | W21: PERM | X21: S4 Cloud | Y21: =E21/$W$2 -> 0 | Z21: =F21/$W$2 -> 0 | AA21: =G21/$W$2 -> 0 | AB21: =H21/$W$2 -> 0 | AC21: =I21/$W$2 -> 16816.143 | AD21: 0
B22: Rodney Govender | C22: TEMP | D22: S4 Cloud | E22: ='S4 Cloud Contractor Data'!C84 -> 29200 | F22: ='S4 Cloud Contractor Data'!D84 -> 29200 | G22: ='S4 Cloud Contractor Data'!E84 -> 25200 | H22: =SUM(E22:G22) -> 83600 | I22: 340000 | J22: =H22/I22 -> 0.24588235 | L22: Rodney Govender | M22: TEMP | N22: S4 Cloud | O22: =E22/$M$2 -> 1751.6497 | P22: =F22/$M$2 -> 1751.6497 | Q22: =G22/$M$2 -> 1511.6977 | R22: =H22/$M$2 -> 5014.997 | S22: =I22/$M$2 -> 20395.921 | T22: =R22/S22 -> 0.24588235 | V22: Rodney Govender | W22: TEMP | X22: S4 Cloud | Y22: =E22/$W$2 -> 1309.417 | Z22: =F22/$W$2 -> 1309.417 | AA22: =G22/$W$2 -> 1130.0448 | AB22: =H22/$W$2 -> 3748.8789 | AC22: =I22/$W$2 -> 15246.637 | AD22: =AB22/AC22 -> 0.24588235
B23: Mandy Duvenage | C23: TEMP | D23: S4 Cloud | E23: ='S4 Cloud Contractor Data'!C86 -> 96880 | F23: ='S4 Cloud Contractor Data'!D86 -> 96880 | G23: ='S4 Cloud Contractor Data'!E86 -> 92880 | H23: =SUM(E23:G23) -> 286640 | I23: 277875 | J23: =H23/I23 -> 1.031543 | L23: Mandy Duvenage | M23: TEMP | N23: S4 Cloud | O23: =E23/$M$2 -> 5811.6377 | P23: =F23/$M$2 -> 5811.6377 | Q23: =G23/$M$2 -> 5571.6857 | R23: =H23/$M$2 -> 17194.961 | S23: =I23/$M$2 -> 16669.166 | T23: =R23/S23 -> 1.031543 | V23: Mandy Duvenage | W23: TEMP | X23: S4 Cloud | Y23: =E23/$W$2 -> 4344.3946 | Z23: =F23/$W$2 -> 4344.3946 | AA23: =G23/$W$2 -> 4165.0224 | AB23: =H23/$W$2 -> 12853.812 | AC23: =I23/$W$2 -> 12460.762 | AD23: =AB23/AC23 -> 1.031543
B24: Jesse van der Poel | C24: TEMP | D24: S4 Cloud | E24: ='S4 Cloud Contractor Data'!C89 -> 20800 | F24: ='S4 Cloud Contractor Data'!D89 -> 20800 | G24: ='S4 Cloud Contractor Data'!E89 -> 20800 | H24: =SUM(E24:G24) -> 62400 | I24: 150000 | J24: =H24/I24 -> 0.416 | L24: Jesse van der Poel | M24: TEMP | N24: S4 Cloud | O24: =E24/$M$2 -> 1247.7504 | P24: =F24/$M$2 -> 1247.7504 | Q24: =G24/$M$2 -> 1247.7504 | R24: =H24/$M$2 -> 3743.2513 | S24: =I24/$M$2 -> 8998.2004 | T24: =R24/S24 -> 0.416 | V24: Jesse van der Poel | W24: TEMP | X24: S4 Cloud | Y24: =E24/$W$2 -> 932.73543 | Z24: =F24/$W$2 -> 932.73543 | AA24: =G24/$W$2 -> 932.73543 | AB24: =H24/$W$2 -> 2798.2063 | AC24: =I24/$W$2 -> 6726.4574 | AD24: =AB24/AC24 -> 0.416
B25: Sheldon Botha | C25: TEMP | D25: S4 Cloud | E25: ='S4 Cloud Contractor Data'!C88 -> 46880 | F25: ='S4 Cloud Contractor Data'!D88 -> 46880 | G25: ='S4 Cloud Contractor Data'!E88 -> 46880 | H25: =SUM(E25:G25) -> 140640 | I25: 350000 | J25: =H25/I25 -> 0.40182857 | L25: Sheldon Botha | M25: TEMP | N25: S4 Cloud | O25: =E25/$M$2 -> 2812.2376 | P25: =F25/$M$2 -> 2812.2376 | Q25: =G25/$M$2 -> 2812.2376 | R25: =H25/$M$2 -> 8436.7127 | S25: =I25/$M$2 -> 20995.801 | T25: =R25/S25 -> 0.40182857 | V25: Sheldon Botha | W25: TEMP | X25: S4 Cloud | Y25: =E25/$W$2 -> 2102.2422 | Z25: =F25/$W$2 -> 2102.2422 | AA25: =G25/$W$2 -> 2102.2422 | AB25: =H25/$W$2 -> 6306.7265 | AC25: =I25/$W$2 -> 15695.067 | AD25: =AB25/AC25 -> 0.40182857
B26: Tom Harding | C26: TEMP | D26: S4 Cloud | E26: ='S4 Cloud Contractor Data'!C85 -> 74825 | F26: ='S4 Cloud Contractor Data'!D85 -> 74825 | G26: ='S4 Cloud Contractor Data'!E85 -> 74825 | H26: =SUM(E26:G26) -> 224475 | I26: 440000 | J26: =H26/I26 -> 0.51017045 | L26: Tom Harding | M26: TEMP | N26: S4 Cloud | O26: =E26/$M$2 -> 4488.6023 | P26: =F26/$M$2 -> 4488.6023 | Q26: =G26/$M$2 -> 4488.6023 | R26: =H26/$M$2 -> 13465.807 | S26: =I26/$M$2 -> 26394.721 | T26: =R26/S26 -> 0.51017045 | V26: Tom Harding | W26: TEMP | X26: S4 Cloud | Y26: =E26/$W$2 -> 3355.3812 | Z26: =F26/$W$2 -> 3355.3812 | AA26: =G26/$W$2 -> 3355.3812 | AB26: =H26/$W$2 -> 10066.143 | AC26: =I26/$W$2 -> 19730.942 | AD26: =AB26/AC26 -> 0.51017045
B27: Max Goodger | C27: TEMP | D27: S4 Cloud | E27: ='S4 Cloud Contractor Data'!C87 -> 0 | F27: ='S4 Cloud Contractor Data'!D87 -> 0 | G27: ='S4 Cloud Contractor Data'!E87 -> 0 | H27: =SUM(E27:G27) -> 0 | I27: 340000 | J27: =H27/I27 -> 0 | L27: Max Goodger | M27: TEMP | N27: S4 Cloud | O27: =E27/$M$2 -> 0 | P27: =F27/$M$2 -> 0 | Q27: =G27/$M$2 -> 0 | R27: =H27/$M$2 -> 0 | S27: =I27/$M$2 -> 20395.921 | T27: =R27/S27 -> 0 | V27: Max Goodger | W27: TEMP | X27: S4 Cloud | Y27: =E27/$W$2 -> 0 | Z27: =F27/$W$2 -> 0 | AA27: =G27/$W$2 -> 0 | AB27: =H27/$W$2 -> 0 | AC27: =I27/$W$2 -> 15246.637 | AD27: =AB27/AC27 -> 0
R28: =H28/$M$2 -> 0 | S28: =I28/$M$2 -> 0 | AB28: =H28/$W$2 -> 0 | AC28: =I28/$W$2 -> 0
R29: =H29/$M$2 -> 0 | S29: =I29/$M$2 -> 0 | AB29: =H29/$W$2 -> 0 | AC29: =I29/$W$2 -> 0
R30: =H30/$M$2 -> 0 | S30: =I30/$M$2 -> 0 | AB30: =H30/$W$2 -> 0 | AC30: =I30/$W$2 -> 0
R31: =H31/$M$2 -> 0 | S31: =I31/$M$2 -> 0 | AB31: =H31/$W$2 -> 0 | AC31: =I31/$W$2 -> 0
B32: S4 TOTAL | E32: =SUM(E5:E31) -> 444685 | F32: =SUM(F5:F31) -> 296185 | G32: =SUM(G5:G31) -> 288185 | H32: =SUM(H5:H31) -> 1029055 | I32: =SUM(I5:I31) -> 8310875 | J32: =H32/I32 -> 0.1238203 | L32: S4 TOTAL | O32: =E32/$M$2 -> 26675.765 | P32: =F32/$M$2 -> 17767.546 | Q32: =G32/$M$2 -> 17287.642 | R32: =H32/$M$2 -> 61730.954 | S32: =I32/$M$2 -> 498552.79 | T32: =R32/S32 -> 0.1238203 | V32: S4 TOTAL | Y32: =E32/$W$2 -> 19941.031 | Z32: =F32/$W$2 -> 13281.839 | AA32: =G32/$W$2 -> 12923.094 | AB32: =H32/$W$2 -> 46145.964 | AC32: =I32/$W$2 -> 372684.98 | AD32: =AB32/AC32 -> 0.1238203
B33: SMART4 ENERGY | E33: =SUM(E5:E20) -> 176100 | F33: =SUM(F5:F20) -> 27600 | G33: =SUM(G5:G20) -> 27600 | H33: =SUM(H5:H20) -> 231300 | I33: =SUM(I5:I20) -> 6038000 | J33: =H33/I33 -> 0.038307387 | L33: SMART4ENERGY | O33: =E33/$M$2 -> 10563.887 | P33: =F33/$M$2 -> 1655.6689 | Q33: =G33/$M$2 -> 1655.6689 | R33: =H33/$M$2 -> 13875.225 | S33: =I33/$M$2 -> 362207.56 | T33: =R33/S33 -> 0.038307387 | V33: SMART4ENERGY | Y33: =E33/$W$2 -> 7896.861 | Z33: =F33/$W$2 -> 1237.6682 | AA33: =G33/$W$2 -> 1237.6682 | AB33: =H33/$W$2 -> 10372.197 | AC33: =I33/$W$2 -> 270762.33 | AD33: =AB33/AC33 -> 0.038307387
B34: SMART4 CLOUD | E34: =SUM(E22:E27) -> 268585 | F34: =SUM(F22:F27) -> 268585 | G34: =SUM(G22:G27) -> 260585 | H34: =SUM(H21:H27) -> 797755 | I34: =SUM(I21:I27) -> 2272875 | J34: =H34/I34 -> 0.35098939 | L34: SMART4CLOUD | O34: =E34/$M$2 -> 16111.878 | P34: =F34/$M$2 -> 16111.878 | Q34: =G34/$M$2 -> 15631.974 | R34: =H34/$M$2 -> 47855.729 | S34: =I34/$M$2 -> 136345.23 | T34: =R34/S34 -> 0.35098939 | V34: SMART4CLOUD | Y34: =E34/$W$2 -> 12044.17 | Z34: =F34/$W$2 -> 12044.17 | AA34: =G34/$W$2 -> 11685.426 | AB34: =H34/$W$2 -> 35773.767 | AC34: =I34/$W$2 -> 101922.65 | AD34: =AB34/AC34 -> 0.35098939
B35: PERM | E35: ='Perm NFI data'!H32 -> 148500 | F35: ='Perm NFI data'!H33 -> 0 | G35: ='Perm NFI data'!H34 -> 0 | H35: =SUM(E35:G35) -> 148500 | L35: PERM | O35: =E35/$M$2 -> 8908.2184 | P35: =F35/$M$2 -> 0 | Q35: =G35/$M$2 -> 0 | R35: =H35/$M$2 -> 8908.2184 | V35: PERM | Y35: =E35/$W$2 -> 6659.1928 | Z35: =F35/$W$2 -> 0 | AA35: =G35/$W$2 -> 0 | AB35: =H35/$W$2 -> 6659.1928
B36: CONTRACT | E36: ='S4 Cloud Contractor Data'!C95 -> 296185 | F36: ='S4 Cloud Contractor Data'!D95 -> 296185 | G36: ='S4 Cloud Contractor Data'!E95 -> 288185 | H36: =SUM(E36:G36) -> 880555 | L36: CONTRACT | O36: =E36/$M$2 -> 17767.546 | P36: =F36/$M$2 -> 17767.546 | Q36: =G36/$M$2 -> 17287.642 | R36: =H36/$M$2 -> 52822.735 | V36: CONTRACT | Y36: =E36/$W$2 -> 13281.839 | Z36: =F36/$W$2 -> 13281.839 | AA36: =G36/$W$2 -> 12923.094 | AB36: =H36/$W$2 -> 39486.771

Sheet Consultant NBV League
B2: Q1 NFI ZAR | L2: Q1 NFI USD | M2: 16.67 | V2: Q1 NFI GBP | W2: 22.3
B4: Consultant / Month | C4: Perm / Temp | D4: Business | E4: Apr | F4: May | G4: Jun | H4: Q1 Actual | I4: Q1 Target | J4: % Achieved | L4: Consultant / Month | M4: Perm / Temp | N4: Business | O4: Apr | P4: May | Q4: Jun | R4: Q1 Actual | S4: Q1 Target | T4: % Achieved | V4: Consultant / Month | W4: Perm / Temp | X4: Business | Y4: Apr | Z4: May | AA4: Jun | AB4: Q1 Actual | AC4: Q1 Target | AD4: % Achieved
B5: Lee Bishop | C5: PERM | D5: S4ENERGY | E5: 0 | F5: 0 | G5: 0 | I5: 900000 | L5: Lee Bishop | M5: PERM | N5: S4ENERGY | O5: =E5/$M$2 -> 0 | P5: =F5/$M$2 -> 0 | Q5: =G5/$M$2 -> 0 | R5: =H5/$M$2 -> 0 | S5: =I5/$M$2 -> 53989.202 | V5: Lee Bishop | W5: PERM | X5: S4ENERGY | Y5: =E5/$W$2 -> 0 | Z5: =F5/$W$2 -> 0 | AA5: =G5/$W$2 -> 0 | AB5: =H5/$W$2 -> 0 | AC5: =I5/$W$2 -> 40358.744
B6: Warren Beder | C6: PERM | D6: S4ENERGY | E6: 0 | F6: 0 | G6: 0 | I6: 900000 | L6: Warren Beder | M6: PERM | N6: S4ENERGY | O6: =E6/$M$2 -> 0 | P6: =F6/$M$2 -> 0 | Q6: =G6/$M$2 -> 0 | R6: =H6/$M$2 -> 0 | S6: =I6/$M$2 -> 53989.202 | V6: Warren Beder | W6: PERM | X6: S4ENERGY | Y6: =E6/$W$2 -> 0 | Z6: =F6/$W$2 -> 0 | AA6: =G6/$W$2 -> 0 | AB6: =H6/$W$2 -> 0 | AC6: =I6/$W$2 -> 40358.744
B7: Lufuno Orji* | C7: PERM | D7: S4ENERGY | E7: 0 | F7: 0 | G7: 0 | I7: 525000 | L7: Lufuno Orji* | M7: PERM | N7: S4ENERGY | O7: =E7/$M$2 -> 0 | P7: =F7/$M$2 -> 0 | Q7: =G7/$M$2 -> 0 | R7: =H7/$M$2 -> 0 | S7: =I7/$M$2 -> 31493.701 | V7: Lufuno Orji* | W7: PERM | X7: S4ENERGY | Y7: =E7/$W$2 -> 0 | Z7: =F7/$W$2 -> 0 | AA7: =G7/$W$2 -> 0 | AB7: =H7/$W$2 -> 0 | AC7: =I7/$W$2 -> 23542.601
B8: Kyla Morgan | C8: PERM | D8: S4ENERGY | E8: 0 | F8: 0 | G8: 0 | I8: 510000 | L8: Kyla Morgan | M8: PERM | N8: S4ENERGY | O8: =E8/$M$2 -> 0 | P8: =F8/$M$2 -> 0 | Q8: =G8/$M$2 -> 0 | R8: =H8/$M$2 -> 0 | S8: =I8/$M$2 -> 30593.881 | V8: Kyla Morgan | W8: PERM | X8: S4ENERGY | Y8: =E8/$W$2 -> 0 | Z8: =F8/$W$2 -> 0 | AA8: =G8/$W$2 -> 0 | AB8: =H8/$W$2 -> 0 | AC8: =I8/$W$2 -> 22869.955
B9: Zara Kavalieratos | C9: PERM | D9: S4ENERGY | E9: 0 | F9: 0 | G9: 0 | I9: 450000 | L9: Zara Kavalieratos | M9: PERM | N9: S4ENERGY | O9: =E9/$M$2 -> 0 | P9: =F9/$M$2 -> 0 | Q9: =G9/$M$2 -> 0 | R9: =H9/$M$2 -> 0 | S9: =I9/$M$2 -> 26994.601 | V9: Zara Kavalieratos | W9: PERM | X9: S4ENERGY | Y9: =E9/$W$2 -> 0 | Z9: =F9/$W$2 -> 0 | AA9: =G9/$W$2 -> 0 | AB9: =H9/$W$2 -> 0 | AC9: =I9/$W$2 -> 20179.372
B10: JP Roos | C10: PERM | D10: S4ENERGY | E10: 0 | F10: 0 | G10: 0 | I10: 450000 | L10: JP Roos | M10: PERM | N10: S4ENERGY | O10: =E10/$M$2 -> 0 | P10: =F10/$M$2 -> 0 | Q10: =G10/$M$2 -> 0 | R10: =H10/$M$2 -> 0 | S10: =I10/$M$2 -> 26994.601 | V10: JP Roos | W10: PERM | X10: S4ENERGY | Y10: =E10/$W$2 -> 0 | Z10: =F10/$W$2 -> 0 | AA10: =G10/$W$2 -> 0 | AB10: =H10/$W$2 -> 0 | AC10: =I10/$W$2 -> 20179.372
B11: Matthew Taylor | C11: PERM | D11: S4ENERGY | E11: 0 | F11: 0 | G11: 0 | I11: 450000 | L11: Matthew Taylor | M11: PERM | N11: S4ENERGY | O11: =E11/$M$2 -> 0 | P11: =F11/$M$2 -> 0 | Q11: =G11/$M$2 -> 0 | R11: =H11/$M$2 -> 0 | S11: =I11/$M$2 -> 26994.601 | V11: Matthew Taylor | W11: PERM | X11: S4ENERGY | Y11: =E11/$W$2 -> 0 | Z11: =F11/$W$2 -> 0 | AA11: =G11/$W$2 -> 0 | AB11: =H11/$W$2 -> 0 | AC11: =I11/$W$2 -> 20179.372
B12: Nicole Samuels* | C12: PERM | D12: S4ENERGY | E12: 0 | F12: 0 | G12: 0 | I12: 648000 | L12: Nicole Samuels* | M12: PERM | N12: S4ENERGY | O12: =E12/$M$2 -> 0 | P12: =F12/$M$2 -> 0 | Q12: =G12/$M$2 -> 0 | R12: =H12/$M$2 -> 0 | S12: =I12/$M$2 -> 38872.226 | V12: Nicole Samuels* | W12: PERM | X12: S4ENERGY | Y12: =E12/$W$2 -> 0 | Z12: =F12/$W$2 -> 0 | AA12: =G12/$W$2 -> 0 | AB12: =H12/$W$2 -> 0 | AC12: =I12/$W$2 -> 29058.296
B13: Robyn Andreka | C13: PERM | D13: S4ENERGY | E13: 0 | F13: 0 | G13: 0 | I13: 405000 | L13: Robyn Andreka | M13: PERM | N13: S4ENERGY | O13: =E13/$M$2 -> 0 | P13: =F13/$M$2 -> 0 | Q13: =G13/$M$2 -> 0 | R13: =H13/$M$2 -> 0 | S13: =I13/$M$2 -> 24295.141 | V13: Robyn Andreka | W13: PERM | X13: S4ENERGY | Y13: =E13/$W$2 -> 0 | Z13: =F13/$W$2 -> 0 | AA13: =G13/$W$2 -> 0 | AB13: =H13/$W$2 -> 0 | AC13: =I13/$W$2 -> 18161.435
B14: Nikkita Elliot | C14: PERM | D14: S4ENERGY | E14: 0 | F14: 0 | G14: 0 | I14: 50000 | L14: Nikkita Elliot | M14: PERM | N14: S4ENERGY | O14: =E14/$M$2 -> 0 | P14: =F14/$M$2 -> 0 | Q14: =G14/$M$2 -> 0 | R14: =H14/$M$2 -> 0 | S14: =I14/$M$2 -> 2999.4001 | V14: Nikkita Elliot | W14: PERM | X14: S4ENERGY | Y14: =E14/$W$2 -> 0 | Z14: =F14/$W$2 -> 0 | AA14: =G14/$W$2 -> 0 | AB14: =H14/$W$2 -> 0 | AC14: =I14/$W$2 -> 2242.1525
B15: Mae Alwahi | C15: PERM | D15: S4ENERGY | E15: 0 | F15: 0 | G15: 0 | I15: 150000 | L15: Mae Alwahi | M15: PERM | N15: S4ENERGY | O15: =E15/$M$2 -> 0 | P15: =F15/$M$2 -> 0 | Q15: =G15/$M$2 -> 0 | R15: =H15/$M$2 -> 0 | S15: =I15/$M$2 -> 8998.2004 | V15: Mae Alwahi | W15: PERM | X15: S4ENERGY | Y15: =E15/$W$2 -> 0 | Z15: =F15/$W$2 -> 0 | AA15: =G15/$W$2 -> 0 | AB15: =H15/$W$2 -> 0 | AC15: =I15/$W$2 -> 6726.4574
B16: Christopher Butcher | C16: PERM | D16: S4ENERGY | E16: 0 | F16: 0 | G16: 0 | I16: 300000 | L16: Christopher Butcher | M16: PERM | N16: S4ENERGY | O16: =E16/$M$2 -> 0 | P16: =F16/$M$2 -> 0 | Q16: =G16/$M$2 -> 0 | R16: =H16/$M$2 -> 0 | S16: =I16/$M$2 -> 17996.401 | V16: Christopher Butcher | W16: PERM | X16: S4ENERGY | Y16: =E16/$W$2 -> 0 | Z16: =F16/$W$2 -> 0 | AA16: =G16/$W$2 -> 0 | AB16: =H16/$W$2 -> 0 | AC16: =I16/$W$2 -> 13452.915
... B20: Nina Jacobs | C20: PERM | D20: S4ENERGY | E20: 0 | F20: 0 | G20: 0 | I20: 0 | L20: Nina Jacobs | M20: PERM | N20: S4ENERGY | O20: =E20/$M$2 -> 0 | P20: =F20/$M$2 -> 0 | Q20: =G20/$M$2 -> 0 | R20: =H20/$M$2 -> 0 | S20: =I20/$M$2 -> 0 | V20: Nina Jacobs | W20: PERM | X20: S4ENERGY | Y20: =E20/$W$2 -> 0 | Z20: =F20/$W$2 -> 0 | AA20: =G20/$W$2 -> 0 | AB20: =H20/$W$2 -> 0 | AC20: =I20/$W$2 -> 0
B21: Rodney Govender | C21: TEMP | D21: S4CLOUD | E21: 0 | F21: 0 | G21: 0 | H21: =SUM(E21:G21) -> 0 | I21: 810000 | J21: =H21/I21 -> 0 | L21: Rodney Govender | M21: TEMP | N21: S4CLOUD | O21: =E21/$M$2 -> 0 | P21: =F21/$M$2 -> 0 | Q21: =G21/$M$2 -> 0 | R21: =H21/$M$2 -> 0 | S21: =I21/$M$2 -> 48590.282 | T21: =R21/S21 -> 0 | V21: Rodney Govender | W21: TEMP | X21: S4CLOUD | Y21: =E21/$W$2 -> 0 | Z21: =F21/$W$2 -> 0 | AA21: =G21/$W$2 -> 0 | AB21: =H21/$W$2 -> 0 | AC21: =I21/$W$2 -> 36322.87 | AD21: =AB21/AC21 -> 0
B22: Stephanie Payne | C22: PERM | D22: S4CLOUD | E22: 0 | F22: 0 | G22: 0 | H22: =SUM(E22:G22) -> 0 | I22: 450000 | J22: 0 | L22: Stephanie Payne | M22: PERM | N22: S4CLOUD | O22: =E22/$M$2 -> 0 | P22: =F22/$M$2 -> 0 | Q22: =G22/$M$2 -> 0 | R22: =H22/$M$2 -> 0 | S22: =I22/$M$2 -> 26994.601 | T22: 0 | V22: Stephanie Payne | W22: PERM | X22: S4CLOUD | Y22: =E22/$W$2 -> 0 | Z22: =F22/$W$2 -> 0 | AA22: =G22/$W$2 -> 0 | AB22: =H22/$W$2 -> 0 | AC22: =I22/$W$2 -> 20179.372 | AD22: 0
B23: Mandy Duvenage | C23: TEMP | D23: S4CLOUD | E23: 0 | F23: 0 | G23: 0 | H23: =SUM(E23:G23) -> 0 | I23: 520000 | J23: =H23/I23 -> 0 | L23: Mandy Duvenage | M23: TEMP | N23: S4CLOUD | O23: =E23/$M$2 -> 0 | P23: =F23/$M$2 -> 0 | Q23: =G23/$M$2 -> 0 | R23: =H23/$M$2 -> 0 | S23: =I23/$M$2 -> 31193.761 | T23: =R23/S23 -> 0 | V23: Mandy Duvenage | W23: TEMP | X23: S4CLOUD | Y23: =E23/$W$2 -> 0 | Z23: =F23/$W$2 -> 0 | AA23: =G23/$W$2 -> 0 | AB23: =H23/$W$2 -> 0 | AC23: =I23/$W$2 -> 23318.386 | AD23: =AB23/AC23 -> 0
B24: Jesse van der Poel | C24: TEMP | D24: S4CLOUD | E24: 0 | F24: 0 | G24: 0 | H24: =SUM(E24:G24) -> 0 | I24: 350000 | J24: =H24/I24 -> 0 | L24: Jesse van der Poel | M24: TEMP | N24: S4CLOUD | O24: =E24/$M$2 -> 0 | P24: =F24/$M$2 -> 0 | Q24: =G24/$M$2 -> 0 | R24: =H24/$M$2 -> 0 | S24: =I24/$M$2 -> 20995.801 | T24: =R24/S24 -> 0 | V24: Jesse van der Poel | W24: TEMP | X24: S4CLOUD | Y24: =E24/$W$2 -> 0 | Z24: =F24/$W$2 -> 0 | AA24: =G24/$W$2 -> 0 | AB24: =H24/$W$2 -> 0 | AC24: =I24/$W$2 -> 15695.067 | AD24: =AB24/AC24 -> 0
B25: Sheldon Botha | C25: TEMP | D25: S4CLOUD | E25: 0 | F25: 0 | G25: 0 | H25: =SUM(E25:G25) -> 0 | I25: 520000 | J25: =H25/I25 -> 0 | L25: Sheldon Botha | M25: TEMP | N25: S4CLOUD | O25: =E25/$M$2 -> 0 | P25: =F25/$M$2 -> 0 | Q25: =G25/$M$2 -> 0 | R25: =H25/$M$2 -> 0 | S25: =I25/$M$2 -> 31193.761 | T25: =R25/S25 -> 0 | V25: Sheldon Botha | W25: TEMP | X25: S4CLOUD | Y25: =E25/$W$2 -> 0 | Z25: =F25/$W$2 -> 0 | AA25: =G25/$W$2 -> 0 | AB25: =H25/$W$2 -> 0 | AC25: =I25/$W$2 -> 23318.386 | AD25: =AB25/AC25 -> 0
B26: Tom Harding | C26: TEMP | D26: S4CLOUD | E26: 0 | F26: 0 | G26: 0 | H26: =SUM(E26:G26) -> 0 | I26: 1200000 | J26: =H26/I26 -> 0 | L26: Tom Harding | M26: TEMP | N26: S4CLOUD | O26: =E26/$M$2 -> 0 | P26: =F26/$M$2 -> 0 | Q26: =G26/$M$2 -> 0 | R26: =H26/$M$2 -> 0 | S26: =I26/$M$2 -> 71985.603 | T26: =R26/S26 -> 0 | V26: Tom Harding | W26: TEMP | X26: S4CLOUD | Y26: =E26/$W$2 -> 0 | Z26: =F26/$W$2 -> 0 | AA26: =G26/$W$2 -> 0 | AB26: =H26/$W$2 -> 0 | AC26: =I26/$W$2 -> 53811.659 | AD26: =AB26/AC26 -> 0
B27: Max Goodger | C27: TEMP | D27: S4CLOUD | E27: 0 | F27: 0 | G27: 0 | H27: =SUM(E27:G27) -> 0 | I27: 800000 | J27: =H27/I27 -> 0 | L27: Max Goodger | M27: TEMP | N27: S4CLOUD | O27: =E27/$M$2 -> 0 | P27: =F27/$M$2 -> 0 | Q27: =G27/$M$2 -> 0 | R27: =H27/$M$2 -> 0 | S27: =I27/$M$2 -> 47990.402 | T27: =R27/S27 -> 0 | V27: Max Goodger | W27: TEMP | X27: S4CLOUD | Y27: =E27/$W$2 -> 0 | Z27: =F27/$W$2 -> 0 | AA27: =G27/$W$2 -> 0 | AB27: =H27/$W$2 -> 0 | AC27: =I27/$W$2 -> 35874.439 | AD27: =AB27/AC27 -> 0
R28: =H28/$M$2 -> 0 | S28: =I28/$M$2 -> 0 | AB28: =H28/$W$2 -> 0 | AC28: =I28/$W$2 -> 0
R29: =H29/$M$2 -> 0 | S29: =I29/$M$2 -> 0 | AB29: =H29/$W$2 -> 0 | AC29: =I29/$W$2 -> 0
R30: =H30/$M$2 -> 0 | S30: =I30/$M$2 -> 0 | AB30: =H30/$W$2 -> 0 | AC30: =I30/$W$2 -> 0
R31: =H31/$M$2 -> 0 | S31: =I31/$M$2 -> 0 | AB31: =H31/$W$2 -> 0 | AC31: =I31/$W$2 -> 0
B32: S4 TOTAL | E32: =SUM(E5:E31) -> 0 | F32: =SUM(F5:F31) -> 0 | G32: =SUM(G5:G31) -> 0 | H32: =SUM(H5:H31) -> 0 | I32: =SUM(I5:I31) -> 10688000 | J32: =H32/I32 -> 0 | L32: S4 TOTAL | O32: =E32/$M$2 -> 0 | P32: =F32/$M$2 -> 0 | Q32: =G32/$M$2 -> 0 | R32: =H32/$M$2 -> 0 | S32: =I32/$M$2 -> 641151.77 | T32: =R32/S32 -> 0 | V32: S4 TOTAL | Y32: =E32/$W$2 -> 0 | Z32: =F32/$W$2 -> 0 | AA32: =G32/$W$2 -> 0 | AB32: =H32/$W$2 -> 0 | AC32: =I32/$W$2 -> 479282.51 | AD32: =AB32/AC32 -> 0
B33: SMART4ENERGY | E33: =SUM(E5:E20) -> 0 | F33: =SUM(F5:F20) -> 0 | G33: =SUM(G5:G20) -> 0 | H33: =SUM(H5:H20) -> 0 | I33: =SUM(I5:I20) -> 6038000 | J33: =H33/I33 -> 0 | L33: SMART4ENERGY | O33: =E33/$M$2 -> 0 | P33: =F33/$M$2 -> 0 | Q33: =G33/$M$2 -> 0 | R33: =H33/$M$2 -> 0 | S33: =I33/$M$2 -> 362207.56 | T33: =R33/S33 -> 0 | V33: SMART4ENERGY | Y33: =E33/$W$2 -> 0 | Z33: =F33/$W$2 -> 0 | AA33: =G33/$W$2 -> 0 | AB33: =H33/$W$2 -> 0 | AC33: =I33/$W$2 -> 270762.33 | AD33: =AB33/AC33 -> 0
B34: SMART4CLOUD | E34: =SUM(E21:E27) -> 0 | F34: =SUM(F21:F27) -> 0 | G34: =SUM(G21:G27) -> 0 | H34: =SUM(H21:H27) -> 0 | I34: =SUM(I21:I27) -> 4650000 | J34: =H34/I34 -> 0 | L34: SMART4CLOUD | O34: =E34/$M$2 -> 0 | P34: =F34/$M$2 -> 0 | Q34: =G34/$M$2 -> 0 | R34: =H34/$M$2 -> 0 | S34: =I34/$M$2 -> 278944.21 | T34: =R34/S34 -> 0 | V34: SMART4CLOUD | Y34: =E34/$W$2 -> 0 | Z34: =F34/$W$2 -> 0 | AA34: =G34/$W$2 -> 0 | AB34: =H34/$W$2 -> 0 | AC34: =I34/$W$2 -> 208520.18 | AD34: =AB34/AC34 -> 0

Sheet Perm NFI data
A1: NBV Week | B1: NBV month | C1: REGION | D1: BUSINESS UNIT | E1: IOA / IOS | F1: Placement ID | G1: Value (ZAR) | H1: Start Month | I1: Invoice / Credit Month | J1: Start Day | K1: BH Placement ID | L1: Invoice Sent, Received & Correct? | M1: Conf. of Start? | N1: Client | O1: CANDIDATE | P1: POSITION | Q1: CONSULTANT | R1: RESOURCER | T1: LEE B | U1: ROBYN A | V1: NIKITA E | W1: NICOLE S | X1: HOUSE ENERGY | Y1: MATT T | Z1: KYLA G | AA1: MAE A | AB1: ZARA K | AC1: JP ROOS | AD1: WARREN B | AE1: LUFUNO O | AF1: NINA J | AG1: JOSH W | AH1: STEPH P | AI1: MANDY D | AJ1: SHELDON B | AK1: ROD G | AL1: JESSE V | AM1: LARA JVR
A2: 11 | B2: March | C2: South Africa | D2: ENERGY | E2: IOS | G2: 148500 | H2: April | I2: April | J2: 16 | N2: Multotech | O2: Amukelani Mashave | P2: Procurement Manager | Q2: Lufuno O | R2: Warren B | AD2: 74250 | AE2: 74250
D17: PPH | E17: # HEADS
C18: =D18/24 -> 363.97059 | D18: =H18/E18 -> 8735.2941 | E18: 17 | F18: NBV | G18: APRIL | H18: =SUM(T18:AL18) -> 148500 | I18: =H18/24 -> 6187.5 | T18: =SUM(T2:T12) -> 0 | U18: =SUM(U2:U12) -> 0 | V18: =SUM(V2:V12) -> 0 | W18: =SUM(W2:W12) -> 0 | X18: =SUM(X2:X12) -> 0 | Y18: =SUM(Y2:Y12) -> 0 | Z18: =SUM(Z2:Z12) -> 0 | AA18: =SUM(AA2:AA12) -> 0 | ... AM18: =SUM(AM2:AM12) -> 0
C19: =D19/24 -> #REF! | D19: =H19/E19 -> #REF! | E19: 17 | G19: MAY | H19: =SUM(T19:AL19) -> #REF! | I19: =H19/24 -> #REF! | T19: =SUM(#REF!) -> #REF! | U19: =SUM(#REF!) -> #REF! | V19: =SUM(#REF!) -> #REF! | W19: =SUM(#REF!) -> #REF! | X19: =SUM(#REF!) -> #REF! | Y19: =SUM(#REF!) -> #REF! | Z19: =SUM(#REF!) -> #REF! | AA19: =SUM(#REF!) -> #REF! | ... AM19: =SUM(#REF!) -> #REF!
C20: =D20/24 -> #REF! | D20: =H20/E20 -> #REF! | E20: 16 | G20: JUNE | H20: =SUM(T20:AL20) -> #REF! | I20: =H20/24 -> #REF! | T20: =SUM(#REF!) -> #REF! | U20: =SUM(#REF!) -> #REF! | V20: =SUM(#REF!) -> #REF! | W20: =SUM(#REF!) -> #REF! | X20: =SUM(#REF!) -> #REF! | Y20: =SUM(#REF!) -> #REF! | Z20: =SUM(#REF!) -> #REF! | AA20: =SUM(#REF!) -> #REF! | ... AM20: =SUM(#REF!) -> #REF!
C21: =D21/24 -> #REF! | D21: =H21/E21 -> #REF! | E21: 16 | G21: JULY | H21: =SUM(T21:AL21) -> #REF! | I21: =H21/24 -> #REF! | T21: =SUM(#REF!) -> #REF! | U21: =SUM(#REF!) -> #REF! | V21: =SUM(#REF!) -> #REF! | W21: =SUM(#REF!) -> #REF! | X21: =SUM(#REF!) -> #REF! | Y21: =SUM(#REF!) -> #REF! | Z21: =SUM(#REF!) -> #REF! | AA21: =SUM(#REF!) -> #REF! | ... AM21: =SUM(#REF!) -> #REF!
G22: AUGUST | H22: =SUM(T22:AL22) -> #REF! | I22: =H22/24 -> #REF! | T22: =SUM(#REF!) -> #REF! | U22: =SUM(#REF!) -> #REF! | V22: =SUM(#REF!) -> #REF! | W22: =SUM(#REF!) -> #REF! | X22: =SUM(#REF!) -> #REF! | Y22: =SUM(#REF!) -> #REF! | Z22: =SUM(#REF!) -> #REF! | AA22: =SUM(#REF!) -> #REF! | ... AM22: =SUM(#REF!) -> #REF!
G23: SEPTEMBER | H23: =SUM(T23:AL23) -> #REF! | I23: =H23/24 -> #REF! | T23: =SUM(#REF!) -> #REF! | U23: =SUM(#REF!) -> #REF! | V23: =SUM(#REF!) -> #REF! | W23: =SUM(#REF!) -> #REF! | X23: =SUM(#REF!) -> #REF! | Y23: =SUM(#REF!) -> #REF! | Z23: =SUM(#REF!) -> #REF! | AA23: =SUM(#REF!) -> #REF! | ... AM23: =SUM(#REF!) -> #REF!
G24: OCTOBER | H24: =SUM(T24:AL24) -> #REF! | I24: =H24/24 -> #REF! | T24: =SUM(#REF!) -> #REF! | U24: =SUM(#REF!) -> #REF! | V24: =SUM(#REF!) -> #REF! | W24: =SUM(#REF!) -> #REF! | X24: =SUM(#REF!) -> #REF! | Y24: =SUM(#REF!) -> #REF! | Z24: =SUM(#REF!) -> #REF! | AA24: =SUM(#REF!) -> #REF! | ... AM24: =SUM(#REF!) -> #REF!
G25: NOVEMBER | H25: =SUM(T25:AL25) -> #REF! | I25: =H25/22.5 -> #REF! | T25: =SUM(#REF!) -> #REF! | U25: =SUM(#REF!) -> #REF! | V25: =SUM(#REF!) -> #REF! | W25: =SUM(#REF!) -> #REF! | X25: =SUM(#REF!) -> #REF! | Y25: =SUM(#REF!) -> #REF! | Z25: =SUM(#REF!) -> #REF! | AA25: =SUM(#REF!) -> #REF! | ... AM25: =SUM(#REF!) -> #REF!
G26: DECEMBER | H26: =SUM(T26:AL26) -> #REF! | I26: =H26/22.5 -> #REF! | T26: =SUM(#REF!) -> #REF! | U26: =SUM(#REF!) -> #REF! | V26: =SUM(#REF!) -> #REF! | W26: =SUM(#REF!) -> #REF! | X26: =SUM(#REF!) -> #REF! | Y26: =SUM(#REF!) -> #REF! | Z26: =SUM(#REF!) -> #REF! | AA26: =SUM(#REF!) -> #REF! | ... AM26: =SUM(#REF!) -> #REF!
G27: JANUARY | H27: =SUM(T27:AM27) -> #REF! | I27: =H27/24 -> #REF! | T27: =SUM(#REF!) -> #REF! | U27: =SUM(#REF!) -> #REF! | V27: =SUM(#REF!) -> #REF! | W27: =SUM(#REF!) -> #REF! | X27: =SUM(#REF!) -> #REF! | Y27: =SUM(#REF!) -> #REF! | Z27: =SUM(#REF!) -> #REF! | AA27: =SUM(#REF!) -> #REF! | ... AM27: =SUM(#REF!) -> #REF!
G28: FEBRUARY | H28: =SUM(T28:AM28) -> #REF! | I28: =H28/24 -> #REF! | T28: =SUM(#REF!) -> #REF! | U28: =SUM(#REF!) -> #REF! | V28: =SUM(#REF!) -> #REF! | W28: =SUM(#REF!) -> #REF! | X28: =SUM(#REF!) -> #REF! | Y28: =SUM(#REF!) -> #REF! | Z28: =SUM(#REF!) -> #REF! | AA28: =SUM(#REF!) -> #REF! | ... AC28: =SUM(#REF!) -> #REF! | AD28: =#REF!+#REF! -> #REF! | AE28: =SUM(#REF!) -> #REF! | AF28: =SUM(AF13:AF13) -> 0 | AG28: =SUM(AG13:AG13) -> 0 | AH28: =SUM(#REF!) -> #REF! | AI28: =SUM(#REF!) -> #REF! | AJ28: =SUM(#REF!) -> #REF! | AK28: =SUM(#REF!) -> #REF! | AL28: =SUM(#REF!) -> #REF! | AM28: =SUM(#REF!) -> #REF!
G29: MARCH | H29: =SUM(T29:AM29) -> 0 | I29: =H29/24 -> 0 | T29: =SUM(T13:T13) -> 0 | U29: =SUM(U13:U13) -> 0 | V29: =SUM(V13:V13) -> 0 | W29: =SUM(W13:W13) -> 0 | X29: =SUM(X13:X13) -> 0 | Y29: =SUM(Y13:Y13) -> 0 | Z29: =SUM(Z13:Z13) -> 0 | AA29: =SUM(AA13:AA13) -> 0 | ... AM29: =SUM(AM13:AM13) -> 0
G30: TOTAL | H30: =SUM(H18:H29) -> #REF! | I30: =H30/24 -> #REF!
C32: =D32/24 -> 363.97059 | D32: =H32/E32 -> 8735.2941 | E32: 17 | F32: NFI | G32: APRIL | H32: =SUM(T32:AL32) -> 148500 | I32: =H32/24 -> 6187.5 | T32: =SUMIF($I2:$I13,"APRIL",T2:T13) -> 0 | U32: =SUMIF($I2:$I13,"APRIL",U2:U13) -> 0 | V32: =SUMIF($I2:$I13,"APRIL",V2:V13) -> 0 | W32: =SUMIF($I2:$I13,"APRIL",W2:W13) -> 0 | X32: =SUMIF($I2:$I13,"APRIL",X2:X13) -> 0 | Y32: =SUMIF($I2:$I13,"APRIL",Y2:Y13) -> 0 | Z32: =SUMIF($I2:$I13,"APRIL",Z2:Z13) -> 0 | AA32: =SUMIF($I2:$I13,"APRIL",AA2:AA13) -> 0 | ... AM32: =SUMIF($I2:$I13,"APRIL",AM2:AM13) -> 0
C33: =D33/24 -> 0 | D33: =H33/E33 -> 0 | E33: 17 | G33: MAY | H33: =SUM(T33:AL33) -> 0 | I33: =H33/24 -> 0 | T33: =SUMIF($I2:$I13,"may",T2:T13) -> 0 | U33: =SUMIF($I2:$I13,"may",U2:U13) -> 0 | V33: =SUMIF($I2:$I13,"may",V2:V13) -> 0 | W33: =SUMIF($I2:$I13,"may",W2:W13) -> 0 | X33: =SUMIF($I2:$I13,"may",X2:X13) -> 0 | Y33: =SUMIF($I2:$I13,"may",Y2:Y13) -> 0 | Z33: =SUMIF($I2:$I13,"may",Z2:Z13) -> 0 | AA33: =SUMIF($I2:$I13,"may",AA2:AA13) -> 0 | ... AM33: =SUMIF($I2:$I13,"may",AM2:AM13) -> 0
C34: =D34/24 -> 0 | D34: =H34/E34 -> 0 | E34: 16 | G34: JUNE | H34: =SUM(T34:AL34) -> 0 | I34: =H34/24 -> 0 | T34: =SUMIF($I2:$I12,"june",T2:T12) -> 0 | U34: =SUMIF($I2:$I12,"june",U2:U12) -> 0 | V34: =SUMIF($I2:$I12,"june",V2:V12) -> 0 | W34: =SUMIF($I2:$I12,"june",W2:W12) -> 0 | X34: =SUMIF($I2:$I12,"june",X2:X12) -> 0 | Y34: =SUMIF($I2:$I12,"june",Y2:Y12) -> 0 | Z34: =SUMIF($I2:$I12,"june",Z2:Z12) -> 0 | AA34: =SUMIF($I2:$I12,"june",AA2:AA12) -> 0 | ... AM34: =SUMIF($I2:$I12,"june",AM2:AM12) -> 0
C35: =D35/24 -> 0 | D35: =H35/E35 -> 0 | E35: 16 | G35: JULY | H35: =SUM(T35:AL35) -> 0 | I35: =H35/24 -> 0 | T35: =SUMIF($I2:$I12,"july",T2:T12) -> 0 | U35: =SUMIF($I2:$I12,"july",U2:U12) -> 0 | V35: =SUMIF($I2:$I12,"july",V2:V12) -> 0 | W35: =SUMIF($I2:$I12,"july",W2:W12) -> 0 | X35: =SUMIF($I2:$I12,"july",X2:X12) -> 0 | Y35: =SUMIF($I2:$I12,"july",Y2:Y12) -> 0 | Z35: =SUMIF($I2:$I12,"july",Z2:Z12) -> 0 | AA35: =SUMIF($I2:$I12,"july",AA2:AA12) -> 0 | ... AM35: =SUMIF($I2:$I12,"july",AM2:AM12) -> 0
C36: =D36/24 -> 0 | D36: =H36/E36 -> 0 | E36: 16 | G36: AUGUST | H36: =SUM(T36:AL36) -> 0 | I36: =H36/24 -> 0 | T36: =SUMIF($I2:$I12,"august",T2:T12) -> 0 | U36: =SUMIF($I4:$I12,"august",U4:U12) -> 0 | V36: =SUMIF($I4:$I12,"august",V4:V12) -> 0 | W36: =SUMIF($I4:$I12,"august",W4:W12) -> 0 | X36: =SUMIF($I4:$I12,"august",X4:X12) -> 0 | Y36: =SUMIF($I4:$I12,"august",Y4:Y12) -> 0 | Z36: =SUMIF($I4:$I12,"august",Z4:Z12) -> 0 | AA36: =SUMIF($I4:$I12,"august",AA4:AA12) -> 0 | AB36: =SUMIF($I4:$I12,"august",AB4:AB12) -> 0 | ... AM36: =SUMIF($I4:$I12,"august",AM4:AM12) -> 0
C37: =D37/24 -> 0 | D37: =H37/E37 -> 0 | E37: 16 | G37: SEPTEMBER | H37: =SUM(T37:AL37) -> 0 | I37: =H37/24 -> 0 | T37: =SUMIF($I2:$I12,"september",T2:T12) -> 0 | U37: =SUMIF($I5:$I12,"september",U5:U12) -> 0 | V37: =SUMIF($I5:$I12,"september",V5:V12) -> 0 | W37: =SUMIF($I5:$I12,"september",W5:W12) -> 0 | X37: =SUMIF($I5:$I12,"september",X5:X12) -> 0 | Y37: =SUMIF($I5:$I12,"september",Y5:Y12) -> 0 | Z37: =SUMIF($I5:$I12,"september",Z5:Z12) -> 0 | AA37: =SUMIF($I5:$I12,"september",AA5:AA12) -> 0 | AB37: =SUMIF($I5:$I12,"september",AB5:AB12) -> 0 | ... AM37: =SUMIF($I5:$I12,"september",AM5:AM12) -> 0
C38: =D38/24 -> 0 | D38: =H38/E38 -> 0 | E38: 17 | G38: OCTOBER | H38: =SUM(T38:AL38) -> 0 | I38: =H38/23 -> 0 | T38: =SUMIF($I2:$I13,"october",T2:T12) -> 0 | U38: =SUMIF($I2:$I13,"october",U2:U12) -> 0 | V38: =SUMIF($I2:$I13,"october",V2:V12) -> 0 | W38: =SUMIF($I2:$I13,"october",W2:W12) -> 0 | X38: =SUMIF($I2:$I13,"october",X2:X12) -> 0 | Y38: =SUMIF($I2:$I13,"october",Y2:Y12) -> 0 | Z38: =SUMIF($I2:$I13,"october",Z2:Z12) -> 0 | AA38: =SUMIF($I2:$I13,"october",AA2:AA12) -> 0 | ... AM38: =SUMIF($I2:$I13,"october",AM2:AM12) -> 0
C39: =D39/24 -> 0 | D39: =H39/E39 -> 0 | E39: 18 | G39: NOVEMBER | H39: =SUM(T39:AL39) -> 0 | I39: =H39/23 -> 0 | T39: =SUMIF($I3:$I13,"november",T3:T13) -> 0 | U39: =SUMIF($I3:$I13,"november",U3:U13) -> 0 | V39: =SUMIF($I3:$I13,"november",V3:V13) -> 0 | W39: =SUMIF($I3:$I13,"november",W3:W13) -> 0 | X39: =SUMIF($I3:$I13,"november",X3:X13) -> 0 | Y39: =SUMIF($I3:$I13,"november",Y3:Y13) -> 0 | Z39: =SUMIF($I3:$I13,"november",Z3:Z13) -> 0 | AA39: =SUMIF($I3:$I13,"november",AA3:AA13) -> 0 | ... AM39: =SUMIF($I3:$I13,"november",AM3:AM13) -> 0
C40: =D40/24 -> 0 | D40: =H40/E40 -> 0 | E40: 19 | G40: DECEMBER | H40: =SUM(T40:AL40) -> 0 | I40: =H40/23 -> 0 | T40: =SUMIF($I4:$I13,"december",T4:T13) -> 0 | U40: =SUMIF($I4:$I13,"december",U4:U13) -> 0 | V40: =SUMIF($I4:$I13,"december",V4:V13) -> 0 | W40: =SUMIF($I4:$I13,"december",W4:W13) -> 0 | X40: =SUMIF($I4:$I13,"december",X4:X13) -> 0 | Y40: =SUMIF($I4:$I13,"december",Y4:Y13) -> 0 | Z40: =SUMIF($I4:$I13,"december",Z4:Z13) -> 0 | AA40: =SUMIF($I4:$I13,"december",AA4:AA13) -> 0 | ... AM40: =SUMIF($I4:$I13,"december",AM4:AM13) -> 0
G41: JANUARY | H41: =SUM(T41:AL41) -> 0 | I41: =H41/24 -> 0 | T41: =SUMIF($I5:$I14,"january",T5:T14) -> 0 | U41: =SUMIF($I5:$I14,"january",U5:U14) -> 0 | V41: =SUMIF($I5:$I14,"january",V5:V14) -> 0 | W41: =SUMIF($I5:$I14,"january",W5:W13) -> 0 | X41: =SUMIF($I5:$I14,"january",X5:X14) -> 0 | Y41: =SUMIF($I5:$I14,"january",Y5:Y14) -> 0 | Z41: =SUMIF($I5:$I14,"january",Z5:Z14) -> 0 | AA41: =SUMIF($I5:$I14,"january",AA5:AA14) -> 0 | AB41: =SUMIF($I5:$I14,"january",AB5:AB14) -> 0 | AC41: =SUMIF($I5:$I14,"january",AC5:AC14) -> 0 | AD41: =SUMIF($I5:$I14,"january",AD5:AD14) -> 0 | AE41: =SUMIF($I5:$I14,"january",AE5:AE14) -> 0 | ... AM41: =SUMIF($I5:$I14,"january",AM5:AM14) -> 0
G42: FEBRUARY | H42: =SUM(T42:AL42) -> 0 | I42: =H42/24 -> 0 | T42: =SUMIF($I6:$I15,"february",T6:T13) -> 0 | U42: =SUMIF($I6:$I15,"february",U6:U13) -> 0 | V42: =SUMIF($I6:$I15,"february",V6:V13) -> 0 | W42: =SUMIF($I6:$I13,"february",W6:W13) -> 0 | X42: =SUMIF($I6:$I15,"february",X6:X13) -> 0 | Y42: =SUMIF($I6:$I15,"february",Y6:Y13) -> 0 | Z42: =SUMIF($I6:$I15,"february",Z6:Z13) -> 0 | AA42: =SUMIF($I6:$I15,"february",AA6:AA13) -> 0 | AB42: =SUMIF($I6:$I15,"february",AB6:AB13) -> 0 | AC42: =SUMIF($I6:$I15,"february",AC6:AC13) -> 0 | AD42: =SUMIF($I6:$I15,"february",AD6:AD13) -> 0 | AE42: =SUMIF($I6:$I15,"february",AE6:AE13) -> 0 | ... AM42: =SUMIF($I6:$I15,"february",AM6:AM13) -> 0
G43: MARCH | H43: =SUM(T43:AL43) -> 0 | I43: =H43/24 -> 0 | T43: =SUMIF($I7:$I16,"march",T7:T16) -> 0 | U43: =SUMIF($I7:$I16,"march",U7:U16) -> 0 | V43: =SUMIF($I7:$I16,"march",V7:V16) -> 0 | W43: =SUMIF($I7:$I16,"march",W7:W16) -> 0 | X43: =SUMIF($I7:$I16,"march",X7:X16) -> 0 | Y43: =SUMIF($I7:$I16,"march",Y7:Y16) -> 0 | Z43: =SUMIF($I7:$I16,"march",Z7:Z16) -> 0 | AA43: =SUMIF($I7:$I16,"march",AA7:AA16) -> 0 | ... AM43: =SUMIF($I7:$I16,"march",AM7:AM16) -> 0
G44: TOTAL | H44: =SUM(H32:H43) -> 148500
F46: STARTERS | G46: APRIL | H46: =SUM(T46:AL46) -> 148500 | I46: =H46/24 -> 6187.5 | T46: =SUMIF($H2:$H13,"APRIL",T2:T13) -> 0 | U46: =SUMIF($H2:$H13,"APRIL",U2:U13) -> 0 | V46: =SUMIF($H2:$H13,"APRIL",V2:V13) -> 0 | W46: =SUMIF($H2:$H13,"APRIL",W2:W13) -> 0 | X46: =SUMIF($H2:$H13,"APRIL",X2:X13) -> 0 | Y46: =SUMIF($H2:$H13,"APRIL",Y2:Y13) -> 0 | Z46: =SUMIF($H2:$H13,"APRIL",Z2:Z13) -> 0 | AA46: =SUMIF($H2:$H13,"APRIL",AA2:AA13) -> 0 | ... AM46: =SUMIF($H2:$H13,"APRIL",AM2:AM13) -> 0
G47: MAY | H47: =SUM(T47:AL47) -> 0 | I47: =H47/24 -> 0 | T47: =SUMIF($H2:$H13,"may",T2:T13) -> 0 | U47: =SUMIF($H2:$H13,"may",U2:U13) -> 0 | V47: =SUMIF($H2:$H13,"may",V2:V13) -> 0 | W47: =SUMIF($H2:$H13,"may",W2:W13) -> 0 | X47: =SUMIF($H2:$H13,"may",X2:X13) -> 0 | Y47: =SUMIF($H2:$H13,"may",Y2:Y13) -> 0 | Z47: =SUMIF($H2:$H13,"may",Z2:Z13) -> 0 | AA47: =SUMIF($H2:$H13,"may",AA2:AA13) -> 0 | ... AM47: =SUMIF($H2:$H13,"may",AM2:AM13) -> 0
G48: JUNE | H48: =SUM(T48:AL48) -> 0 | I48: =H48/24 -> 0 | T48: =SUMIF($H2:$H12,"june",T2:T12) -> 0 | U48: =SUMIF($H2:$H12,"june",U2:U12) -> 0 | V48: =SUMIF($H2:$H12,"june",V2:V12) -> 0 | W48: =SUMIF($H2:$H12,"june",W2:W12) -> 0 | X48: =SUMIF($H2:$H12,"june",X2:X12) -> 0 | Y48: =SUMIF($H2:$H12,"june",Y2:Y12) -> 0 | Z48: =SUMIF($H2:$H12,"june",Z2:Z12) -> 0 | AA48: =SUMIF($H2:$H12,"june",AA2:AA12) -> 0 | ... AM48: =SUMIF($H2:$H12,"june",AM2:AM12) -> 0
G49: JULY | H49: =SUM(T49:AL49) -> 0 | I49: =H49/24 -> 0 | T49: =SUMIF($H2:$H12,"july",T2:T12) -> 0 | U49: =SUMIF($H2:$H12,"july",U2:U12) -> 0 | V49: =SUMIF($H2:$H12,"july",V2:V12) -> 0 | W49: =SUMIF($H2:$H12,"july",W2:W12) -> 0 | X49: =SUMIF($H2:$H12,"july",X2:X12) -> 0 | Y49: =SUMIF($H2:$H12,"july",Y2:Y12) -> 0 | Z49: =SUMIF($H2:$H12,"july",Z2:Z12) -> 0 | AA49: =SUMIF($H2:$H12,"july",AA2:AA12) -> 0 | ... AM49: =SUMIF($H2:$H12,"july",AM2:AM12) -> 0
G50: AUGUST | H50: =SUM(T50:AL50) -> 0 | I50: =H50/24 -> 0 | T50: =SUMIF($H3:$H12,"august",T3:T12) -> 0 | U50: =SUMIF($H3:$H12,"august",U3:U12) -> 0 | V50: =SUMIF($H3:$H12,"august",V3:V12) -> 0 | W50: =SUMIF($H3:$H12,"august",W3:W12) -> 0 | X50: =SUMIF($H3:$H12,"august",X3:X12) -> 0 | Y50: =SUMIF($H3:$H12,"august",Y3:Y12) -> 0 | Z50: =SUMIF($H3:$H12,"august",Z3:Z12) -> 0 | AA50: =SUMIF($H3:$H12,"august",AA3:AA12) -> 0 | ... AM50: =SUMIF($H3:$H12,"august",AM3:AM12) -> 0
G51: SEPTEMBER | H51: =SUM(T51:AL51) -> 0 | I51: =H51/24 -> 0 | T51: =SUMIF($H4:$H12,"september",T4:T12) -> 0 | U51: =SUMIF($H4:$H12,"september",U4:U12) -> 0 | V51: =SUMIF($H4:$H12,"september",V4:V12) -> 0 | W51: =SUMIF($H4:$H12,"september",W4:W12) -> 0 | X51: =SUMIF($H4:$H12,"september",X4:X12) -> 0 | Y51: =SUMIF($H4:$H12,"september",Y4:Y12) -> 0 | Z51: =SUMIF($H4:$H12,"september",Z4:Z12) -> 0 | AA51: =SUMIF($H4:$H12,"september",AA4:AA12) -> 0 | ... AM51: =SUMIF($H4:$H12,"september",AM4:AM12) -> 0
G52: OCTOBER | H52: =SUM(T52:AL52) -> 0 | I52: =H52/23 -> 0 | T52: =SUMIF($H5:$H12,"october",T5:T12) -> 0 | U52: =SUMIF($H5:$H12,"october",U5:U12) -> 0 | V52: =SUMIF($H5:$H12,"october",V5:V12) -> 0 | W52: =SUMIF($H5:$H12,"october",W5:W12) -> 0 | X52: =SUMIF($H5:$H12,"october",X5:X12) -> 0 | Y52: =SUMIF($H5:$H12,"october",Y5:Y12) -> 0 | Z52: =SUMIF($H5:$H12,"october",Z5:Z12) -> 0 | AA52: =SUMIF($H5:$H12,"october",AA5:AA12) -> 0 | ... AM52: =SUMIF($H5:$H12,"october",AM5:AM12) -> 0
G53: NOVEMBER | H53: =SUM(T53:AL53) -> 0 | I53: =H53/23 -> 0 | T53: =SUMIF($H6:$H13,"november",T2:T13) -> 0 | U53: =SUMIF($H6:$H13,"november",U2:U13) -> 0 | V53: =SUMIF($H6:$H13,"november",V2:V13) -> 0 | W53: =SUMIF($H6:$H13,"november",W2:W13) -> 0 | X53: =SUMIF($H6:$H13,"november",X2:X13) -> 0 | Y53: =SUMIF($H6:$H13,"november",Y2:Y13) -> 0 | Z53: =SUMIF($H6:$H13,"november",Z2:Z13) -> 0 | AA53: =SUMIF($H6:$H13,"november",AA2:AA13) -> 0 | ... AM53: =SUMIF($H6:$H13,"november",AM2:AM13) -> 0
G54: DECEMBER | H54: =SUM(T54:AL54) -> 0 | I54: =H54/23 -> 0 | T54: =SUMIF($H7:$H13,"december",T3:T13) -> 0 | U54: =SUMIF($H7:$H13,"december",U3:U13) -> 0 | V54: =SUMIF($H7:$H13,"december",V3:V13) -> 0 | W54: =SUMIF($H7:$H13,"december",W3:W13) -> 0 | X54: =SUMIF($H7:$H13,"december",X3:X13) -> 0 | Y54: =SUMIF($H7:$H13,"december",Y3:Y13) -> 0 | Z54: =SUMIF($H7:$H13,"december",Z3:Z13) -> 0 | AA54: =SUMIF($H7:$H13,"december",AA3:AA13) -> 0 | ... AM54: =SUMIF($H7:$H13,"december",AM3:AM13) -> 0
G55: JANUARY | H55: =SUM(T55:AL55) -> 0 | I55: =H55/23 -> 0 | T55: =SUMIF($H8:$H13,"January",T4:T13) -> 0 | U55: =SUMIF($H8:$H13,"January",U4:U13) -> 0 | V55: =SUMIF($H8:$H13,"January",V4:V13) -> 0 | W55: =SUMIF($H2:$H13,"January",W4:W13) -> 0 | X55: =SUMIF($H8:$H13,"January",X4:X13) -> 0 | Y55: =SUMIF($H8:$H13,"January",Y4:Y13) -> 0 | Z55: =SUMIF($H8:$H13,"January",Z4:Z13) -> 0 | AA55: =SUMIF($H8:$H13,"January",AA4:AA13) -> 0 | AB55: =SUMIF($H8:$H13,"January",AB4:AB13) -> 0 | AC55: =SUMIF($H8:$H13,"January",AC4:AC13) -> 0 | AD55: =SUMIF($H8:$H13,"January",AD4:AD13) -> 0 | AE55: =SUMIF($H8:$H13,"January",AE4:AE13) -> 0 | ... AM55: =SUMIF($H8:$H13,"January",AM4:AM13) -> 0
G56: FEBRUARY | H56: =SUM(T56:AL56) -> 0 | I56: =H56/23 -> 0
...

Sheet S4 Cloud Contractor Data
A1: Region | C1: Status | D1: NBV Month | E1: NBV Value | F1: NBV Week | G1: Placement ID & Link | H1: Client | I1: Candidate | J1: Payroll / Ltd. Co | K1: Role | L1: Consultant | M1: Resourcer | N1: Start Date | O1: End / Review Date | P1: Currency | Q1: Hourly Rate | R1: Hourly Margin | S1: % | T1: ZAR Margin PD | U1: ZAR Forecast PW | V1: ZAR Forecast GP/ PM | W1: APR > | X1: Rod G | Y1: Mandy D | Z1: Sheldon B | AA1: Jesse V | AB1: Tom H. | AC1: Max G. | AD1: Nicole S. | AE1: Kyla M. | AF1: MAY > | AG1: Rod G | AH1: Mandy D | AI1: Sheldon B | AJ1: Jesse V | AK1: Tom H. | AL1: Max G. | AM1: Nicole S. | AN1: Kyla M. | AO1: JUN > | AP1: Rod G | AQ1: Mandy D | AR1: Sheldon B | AS1: Jesse V | AT1: Tom H. | AU1: Max G. | AV1: Nicole S. | AW1: Kyla M.
A2: SA | B2: Cloud | C2: Live | D2: September | E2: 96000 | F2: 12 | G2: CL-03252025-5075 | H2: Momentum (MHG) | I2: Rex Schelling | J2: Payroll | K2: Agile Coach | L2: Mandy D | M2: Sheldon B | N2: 45747 | O2: 46111 | P2: ZAR | Q2: 570 | R2: 100 | S2: =R2/Q2 -> 0.1754386 | T2: =SUM(U2/5) -> 710 | U2: =SUM(V2/4.5) -> 3550 | V2: 15975 | Y2: 8000 | Z2: 8000 | AH2: 8000 | AI2: 8000 | AQ2: 8000 | AR2: 8000
A3: SA | B3: Cloud | C3: Live | D3: April | E3: 172800 | F3: 15 | G3: CL-04102025-5086 | H3: Momentum (MHG) | I3: Preshantin Moodley | K3: Intermediate Scrum Master | L3: Mandy D | M3: Sheldon B | N3: 45807 | O3: 46156 | P3: ZAR | Q3: 360 | R3: 90 | S3: 0.2 | T3: =SUM(U3/5) -> 721 | U3: =SUM(V3/4,5) -> 3605 | V3: 14400 | Y3: 7200 | Z3: 7200 | AH3: 7200 | AI3: 7200 | AQ3: 7200 | AR3: 7200
A4: SA | B4: Cloud | C4: Live | D4: April | E4: 192000 | F4: 20 | G4: CL-05092025-5108 | H4: Momentum (MHG) | I4: Christoff Lombard | K4: UI Frontend Developer | L4: Mandy D | M4: Jesse VDP | N4: 45810 | O4: 46174 | P4: ZAR | Q4: 360 | R4: 100 | S4: 0.2 | T4: =SUM(U4/5) -> 801 | U4: =SUM(V4/4,5) -> 4005 | V4: 16000 | Y4: 8000 | AA4: 8000 | AH4: 8000 | AJ4: 8000 | AQ4: 8000 | AS4: 8000
A5: SA | B5: Cloud | C5: Live | D5: July | E5: 172800 | F5: 28 | G5: CL-07112025-5142 | H5: Momentum (MHG) | I5: Deyendran Lalalam | J5: Payroll | K5: Scrum Master | L5: Mandy D | M5: Sheldon B | N5: 45854 | O5: 46218 | P5: ZAR | Q5: 370 | R5: 90 | S5: 19,57% | T5: =SUM(U5/5) -> 721 | U5: =SUM(V5/4,5) -> 3605 | V5: 14400 | Y5: 7200 | Z5: 7200 | AH5: 7200 | AI5: 7200 | AQ5: 7200 | AR5: 7200
A6: SA | B6: Cloud | C6: Live | D6: July | E6: 172800 | F6: 28 | G6: CL-07102025-5141 | H6: Momentum (MHG) | I6: Christopher Bickell | J6: Payroll | K6: Scrum Master | L6: Mandy D | M6: Jesse VDP | N6: 45870 | O6: 46234 | P6: ZAR | Q6: 370 | R6: 90 | S6: 19,57% | T6: =SUM(U6/5) -> 721 | U6: =SUM(V6/4,5) -> 3605 | V6: 14400 | Y6: 7200 | AA6: 7200 | AH6: 7200 | AJ6: 7200 | AQ6: 7200 | AS6: 7200
A7: SA | B7: Cloud | C7: Live | D7: July | E7: 120960 | F7: 28 | G7: CL-07142025-5146 | H7: Nexio | I7: Sizwe Thabethe | J7: Payroll | K7: Service Technician | L7: Mandy D | M7: Sheldon B | N7: 45870 | O7: 46234 | P7: ZAR | Q7: 137 | R7: 63 | S7: 31,5% | T7: =SUM(U7/5) -> 505 | U7: =SUM(V7/4,5) -> 2525 | V7: 10080 | Y7: 5040 | Z7: 5040 | AH7: 5040 | AI7: 5040 | AQ7: 5040 | AR7: 5040
A8: SA | B8: Cloud | C8: Live | D8: July | E8: 120960 | F8: 28 | G8: CL-07092025-5140 | H8: Nexio | I8: Brandon Zimri | J8: Payroll | K8: Service Technician | L8: Mandy D | M8: Sheldon B | N8: 45852 | O8: 46216 | P8: ZAR | Q8: 137 | R8: 63 | S8: 31,5% | T8: =SUM(U8/5) -> 505 | U8: =SUM(V8/4,5) -> 2525 | V8: 10080 | Y8: 5040 | Z8: 5040 | AH8: 5040 | AI8: 5040 | AQ8: 5040 | AR8: 5040
A9: SA | B9: Cloud | C9: Live | D9: September | E9: 140160 | F9: 36 | G9: CL-09082025-5198 | H9: Nexio | I9: Innocent Rapula Molaodi | J9: Ltd. | K9: Assurance Engineer Level 2 | L9: Mandy D | M9: Rod G | N9: 45915 | O9: 45991 | P9: ZAR | Q9: 137 | R9: 73 | S9: 33.33 | T9: =SUM(U9/5) -> 519.11111 | U9: =SUM(V9/4.5) -> 2595.5556 | V9: 11680 | X9: 6000 | Y9: 6000 | AG9: 6000 | AH9: 6000 | AP9: 6000 | AQ9: 6000
A10: SA | B10: Cloud | C10: Live | D10: September | E10: 116800 | F10: 38 | G10: CL-09152025-5202 | H10: Decision Inc. | I10: Veloshinie Naidoo | K10: Dynamics BC Consultant | L10: Mandy D | M10: Rod G | N10: 22nd Sept 2025 | O10: 30th April 2026 | P10: ZAR | T10: =SUM(U10/5) -> 711.11111 | U10: =SUM(V10/4.5) -> 3555.5556 | V10: 16000 | X10: 8000 | Y10: 8000 | AG10: 8000 | AH10: 8000 | AP10: 8000 | AQ10: 8000
A11: SA | B11: Cloud | C11: Live | D11: February | E11: 211200 | F11: 8 | H11: Momentum (MHG) | I11: Chanelle Alben | J11: Payroll | K11: Scrum Master | L11: Mandy D | M11: Sheldon B | N11: 46083 | O11: 46447 | P11: ZAR | Q11: 470 | R11: 110 | S11: 0.1896 | T11: =SUM(U11/5) -> 782.22222 | U11: =SUM(V11/4.5) -> 3911.1111 | V11: 17600 | Y11: 8800 | Z11: 8800 | AH11: 8800 | AI11: 8800 | AQ11: 8800 | AR11: 8800
A12: SA | B12: Cloud | C12: Live | D12: February | E12: 134400 | F12: 9 | H12: Momentum (MHG) | I12: Siyanda Dlephu | J12: Payroll | K12: Test Analyst | L12: Mandy D | M12: Rod G | N12: 46113 | O12: 46447 | P12: ZAR | Q12: 350 | R12: 70 | S12: 0.1896 | T12: =SUM(U12/5) -> 497.77778 | U12: =SUM(V12/4.5) -> 2488.8889 | V12: 11200 | X12: 5600 | Y12: 5600 | AG12: 5600 | AH12: 5600 | AP12: 5600 | AQ12: 5600
A13: SA | B13: Cloud | C13: Live | D13: March | E13: 134400 | F13: 10 | H13: Momentum (MHG) | I13: Khomotso Mokobodi | J13: Payroll | K13: Test Analyst | L13: Mandy D | M13: Rod G | N13: 46113 | O13: 46477 | P13: ZAR | Q13: 290 | R13: 70 | S13: =R13/Q13 -> 0.24137931 | T13: =SUM(U13/5) -> 497.77778 | U13: =SUM(V13/4.5) -> 2488.8889 | V13: 11200 | X13: 5600 | Y13: 5600 | AG13: 5600 | AH13: 5600 | AP13: 5600 | AQ13: 5600
A14: SA | B14: Cloud | C14: Live | D14: March | E14: 134400 | F14: 10 | H14: Momentum (MHG) | I14: Aviwe Mngcotane | J14: Payroll | K14: Test Analyst | L14: Mandy D | M14: Sheldon B | N14: 46113 | O14: 46477 | P14: ZAR | R14: 70 | S14: =R14/Q14 -> #DIV/0! | T14: =SUM(U14/5) -> 497.77778 | U14: =SUM(V14/4.5) -> 2488.8889 | V14: 11200 | Y14: 5600 | Z14: 5600 | AH14: 5600 | AI14: 5600 | AQ14: 5600 | AR14: 5600
A15: SA | B15: Cloud | C15: Live | D15: March | E15: 16000 | F15: 10 | H15: Decision Inc. | I15: Bernice Langman | J15: Payroll | K15: Operations Assistant | L15: Mandy D | M15: Rod G | N15: 46079 | O15: 46538 | P15: ZAR | Q15: 90 | R15: 11 | S15: 26%% | T15: =SUM(U15/5) -> 355.55556 | U15: =SUM(V15/4.5) -> 1777.7778 | V15: 8000 | X15: 4000 | Y15: 4000 | AG15: 4000 | AH15: 4000
A16: US | B16: Cloud | C16: Live | H16: Cox | I16: Timothy Hewitt | J16: P2.0 | L16: Tom H | N16: 45870 | O16: 46174 | P16: USD | Q16: 80 | R16: 17 | S16: 20%% | T16: =SUM(U16/5) -> 2047.6 | U16: 10238 | V16: 45425 | AB16: =V16 -> 45425 | AK16: =AB16 -> 45425 | AT16: =AK16 -> 45425
A17: US | B17: Cloud | C17: Live | H17: Cox | I17: Wes Etheridge | J17: L+G | L17: Tom H | N17: 45870 | O17: 46174 | P17: USD | S17: =R17/Q17 -> #DIV/0! | T17: =SUM(U17/5) -> 1668.822 | U17: 8344.11 | V17: 29400 | AB17: =V17 -> 29400 | AK17: =AB17 -> 29400 | AT17: =AK17 -> 29400
A18: SA | B18: Cloud | C18: Live | D18: March | E18: 134400 | F18: 11 | H18: Momentum (MHG) | I18: Thulfiq Brink | J18: Payroll | K18: Test Analyst | L18: Mandy D | M18: Jesse VDP | N18: 46113 | O18: 46477 | P18: 310 | Q18: 70 | S18: =R18/Q18 -> 0 | T18: =SUM(U18/5) -> 497.77778 | U18: =SUM(V18/4.5) -> 2488.8889 | V18: 11200 | Y18: 5600 | AA18: 5600 | AH18: 5600 | AJ18: 5600 | AQ18: 5600 | AS18: 5600
A19: SSA | B19: Energy | C19: Live | D19: October | E19: 86400 | F19: 44 | G19: CL-11032025-5257 | H19: Siemens | I19: Yethu Dlamini | J19: Payroll | K19: Communications Specialist | L19: Nicole S | N19: 45964 | O19: 46326 | S19: =R19/Q19 -> #DIV/0! | T19: =SUM(U19/5) -> 320 | U19: =SUM(V19/4.5) -> 1600 | V19: 7200 | AD19: 7200 | AM19: 7200 | AV19: 7200
A20: SSA | B20: Energy | C20: Live | D20: November | E20: 100800 | F20: 47 | G20: CL-12042025-5325 | H20: Siemens | I20: Siyabonga Zama | J20: Payroll | K20: Hub Accountant | L20: Nicole S | N20: 45992 | O20: 47088 | S20: =R20/Q20 -> #DIV/0! | T20: =SUM(U20/5) -> 373.33333 | U20: =SUM(V20/4.5) -> 1866.6667 | V20: 8400 | AD20: 8400 | AM20: 8400 | AV20: 8400
A21: US | B21: Energy | C21: Live | D21: February | E21: 150000 | F21: 9 | H21: DS CPA Corp. | I21: Olamide Ashade | J21: FTC | K21: CPA | L21: Kyla M | N21: 46090 | P21: USD | S21: =R21/Q21 -> #DIV/0! | T21: =SUM(U21/5) -> 533.33333 | U21: =SUM(V21/4.5) -> 2666.6667 | V21: 12000 | AE21: 12000 | AN21: 12000 | AW21: 12000
A42: =SUM(X2:X41) -> 29200 | X42: =SUM(X2:X40) -> 29200 | Y42: =SUM(Y2:Y40) -> 96880 | Z42: =SUM(Z2:Z40) -> 46880 | AA42: =SUM(AA2:AA40) -> 20800 | AB42: =SUM(AB2:AB40) -> 74825 | AC42: =SUM(AC2:AC40) -> 0 | AD42: =SUM(AD2:AD40) -> 15600 | AE42: =SUM(AE2:AE40) -> 12000 | AG42: =SUM(AG2:AG40) -> 29200 | AH42: =SUM(AH2:AH40) -> 96880 | AI42: =SUM(AI2:AI40) -> 46880 | AJ42: =SUM(AJ2:AJ40) -> 20800 | AK42: =SUM(AK2:AK40) -> 74825 | AL42: =SUM(AL2:AL40) -> 0 | AM42: =SUM(AM2:AM40) -> 15600 | AN42: =SUM(AN2:AN40) -> 12000 | AP42: =SUM(AP2:AP40) -> 25200 | AQ42: =SUM(AQ2:AQ40) -> 92880 | AR42: =SUM(AR2:AR40) -> 46880 | AS42: =SUM(AS2:AS40) -> 20800 | AT42: =SUM(AT2:AT40) -> 74825 | AU42: =SUM(AU2:AU40) -> 0 | AV42: =SUM(AV2:AV40) -> 15600 | AW42: =SUM(AW2:AW40) -> 12000
A44: FX
A45: USD | B45: 16.87
A46: GBP | B46: 22.46
B48: GP FORECAST
A50: USD | B50: Cons / Month | C50: APR | D50: MAY | E50: JUN | F50: JUL | G50: AUG | H50: SEP | I50: OCT | J50: NOV | K50: DEC | L50: JAN | M50: FEB | N50: MAR | O50: Q1 | P50: Q2 | Q50: Q3 | R50: Q4 | S50: HY1 | T50: HY2 | U50: FY27
B51: Rod G. | C51: =C84/$B$45 -> 1730.8832 | D51: =D84/$B$45 -> 1730.8832 | E51: =E84/$B$45 -> 1493.7759 | O51: =SUM(C51:E51) -> 4955.5424 | S51: =SUM(C51:H51) -> 4955.5424 | U51: =SUM(C51:N51) -> 4955.5424
B52: Tom H | C52: =C85/$B$45 -> 4435.3883 | D52: =D85/$B$45 -> 4435.3883 | E52: =E85/$B$45 -> 4435.3883 | O52: =SUM(C52:E52) -> 13306.165 | S52: =SUM(C52:H52) -> 13306.165 | U52: =SUM(C52:N52) -> 13306.165
B53: Mandy D. | C53: =C86/$B$45 -> 5742.7386 | D53: =D86/$B$45 -> 5742.7386 | E53: =E86/$B$45 -> 5505.6313 | O53: =SUM(C53:E53) -> 16991.108 | S53: =SUM(C53:H53) -> 16991.108 | U53: =SUM(C53:N53) -> 16991.108
B54: Max G. | C54: =C87/$B$45 -> 0 | D54: =D87/$B$45 -> 0 | E54: =E87/$B$45 -> 0 | O54: =SUM(C54:E54) -> 0 | S54: =SUM(C54:H54) -> 0 | U54: =SUM(C54:N54) -> 0
B55: Sheldon B. | C55: =C88/$B$45 -> 2778.8975 | D55: =D88/$B$45 -> 2778.8975 | E55: =E88/$B$45 -> 2778.8975 | O55: =SUM(C55:E55) -> 8336.6924 | S55: =SUM(C55:H55) -> 8336.6924 | U55: =SUM(C55:N55) -> 8336.6924
B56: Jesse V. | C56: =C89/$B$45 -> 1232.9579 | D56: =D89/$B$45 -> 1232.9579 | E56: =E89/$B$45 -> 1232.9579 | O56: =SUM(C56:E56) -> 3698.8737 | S56: =SUM(C56:H56) -> 3698.8737 | U56: =SUM(C56:N56) -> 3698.8737
B57: Nicole S. | C57: =C90/$B$45 -> 924.71844 | D57: =D90/$B$45 -> 924.71844 | E57: =E90/$B$45 -> 924.71844 | O57: =SUM(C57:E57) -> 2774.1553 | S57: =SUM(C57:H57) -> 2774.1553 | U57: =SUM(C57:N57) -> 2774.1553
B58: Kyla M | C58: =C91/$B$45 -> 711.32187 | D58: =D91/$B$45 -> 711.32187 | E58: =E91/$B$45 -> 711.32187 | O58: =SUM(C58:E58) -> 2133.9656 | S58: =SUM(C58:H58) -> 2133.9656 | U58: =SUM(C58:N58) -> 2133.9656
B63: TOTALS | C63: =SUM(C51:C57) -> 16845.584 | D63: =SUM(D51:D57) -> 16845.584 | E63: =SUM(E51:E57) -> 16371.369 | F63: =SUM(F51:F57) -> 0 | G63: =SUM(G51:G57) -> 0 | H63: =SUM(H51:H57) -> 0 | I63: =SUM(I51:I57) -> 0 | J63: =SUM(J51:J57) -> 0 | ... N63: =SUM(N51:N57) -> 0 | O63: =SUM(C63:E63) -> 50062.537 | S63: =SUM(C63:H63) -> 50062.537 | U63: =SUM(C63:N63) -> 50062.537
B64: S4 Cloud | C64: =SUM(C51:C56) -> 15920.865 | D64: =SUM(D51:D56) -> 15920.865 | E64: =SUM(E51:E56) -> 15446.651 | O64: =SUM(C64:E64) -> 47288.382 | S64: =SUM(C64:H64) -> 47288.382 | U64: =SUM(C64:N64) -> 47288.382
B65: S4 Energy | C65: =SUM(C57:C58) -> 1636.0403 | D65: =SUM(D57:D58) -> 1636.0403 | E65: =SUM(E57:E58) -> 1636.0403 | O65: =SUM(C65:E65) -> 4908.1209 | S65: =SUM(C65:H65) -> 4908.1209 | U65: =SUM(C65:N65) -> 4908.1209
A67: GBP | B67: Cons / Month | C67: APR | D67: MAY | E67: JUN | F67: JUL | G67: AUG | H67: SEP | I67: OCT | J67: NOV | K67: DEC | L67: JAN | M67: FEB | N67: MAR | O67: Q1 | P67: Q2 | Q67: Q3 | R67: Q4 | S67: HY1 | T67: HY2 | U67: FY27
B68: Rod G. | C68: =C84/$B$46 -> 1300.089 | D68: =D84/$B$46 -> 1300.089 | E68: =E84/$B$46 -> 1121.9947 | O68: =SUM(C68:E68) -> 3722.1728 | S68: =SUM(C68:E68) -> 3722.1728 | U68: =SUM(C68:N68) -> 3722.1728
...

Sheet Contract Commission Bands
B3: New S4Cloud Bands | H3: Current US
B4: USD BANDS (US Based) | D4: COMM.% | E4: ZAR BANDS (SA Based) | H4: BANDS | J4: COMM.%
B5: 0 | C5: 7000 | D5: 0.1 | E5: =B5*16.7 -> 0 | F5: 117000 | H5: 0 | I5: 10000 | J5: 0.1
B6: 7001 | C6: 15000 | D6: 0.15 | E6: 117001 | F6: 250000 | H6: 10001 | I6: 20000 | J6: 0.15
B7: 15001 | C7: 25000 | D7: 0.225 | E7: 250001 | F7: =C7*16.7 -> 417500 | H7: 20001 | I7: 35000 | J7: 0.225
B8: 25001 | C8: 50000 | D8: 0.25 | E8: 417501 | F8: =C8*16.7 -> 835000 | H8: 35001 | I8: 55000 | J8: 0.25
B9: 50001 | C9: 999999 | D9: 0.3 | E9: 835001 | F9: 999999 | H9: 55001 | I9: 999999 | J9: 0.3
B10: PERM | D10: 12,5% | E10: PERM
